Workbook
Name _dataMtr: '12'!$B$5:$S$331
Name _itemMtr: '12'!$B$5:$B$331
Name data: [1]Menu!$A$42:$B$44
Name data: [2]Menu!$A$42:$B$44
Name data: [3]Menu!$A$42:$B$44
Name data: [4]Menu!$A$42:$B$44
Name data: [4]Menu!$A$42:$B$44
Name data: [4]Menu!$A$42:$B$44
Name data: [4]Menu!$A$42:$B$44
Name data: Menu!$A$42:$B$44
Name data_koso: #REF!
Name data_m: #REF!
Name data1: #REF!
Name item: [1]Menu!$A$42:$A$44
Name item: [2]Menu!$A$42:$A$44
Name item: [3]Menu!$A$42:$A$44
Name item: [4]Menu!$A$42:$A$44
Name item: [4]Menu!$A$42:$A$44
Name item: [4]Menu!$A$42:$A$44
Name item: [4]Menu!$A$42:$A$44
Name item: Menu!$A$42:$A$44
Name item_koso: #REF!
Name item_m: #REF!
Name item1: #REF!
Name lineno: '50'!$B$8:$B$40
Name lineno: '51'!#REF!
Name lineno: #REF!
Name status: #REF!
Name ti: #REF!

Sheet Menu
A1: Table of Contents - Qualification of the Maintenance Asset List
A3: ELINS | C3: Qty | E3: MECHANICAL | G3: Qty | I3: CIVIL | K3: Qty
A4: 1 | B4: CONTROL SYSTEM (DCS & RACK ROOM) | C4: ='1'!D79 -> 69 | D4: =C4/C4 -> 1 | E4: =A28+1 -> 26 | F4: AGITATOR | G4: ='26'!D38 -> 17 | H4: =G4/G4 -> 1 | I4: 52 | J4: BUILDING | K4: ='52'!C24 -> 14 | L4: =K4/K4 -> 1
A5: =A4+1 -> 2 | B5: CONTROL VALVE | C5: ='2'!C754 -> 711 | D5: =C5/C5 -> 1 | E5: =E4+1 -> 27 | F5: GEAR PUMP | G5: ='27'!D31 -> 13 | H5: =G5/G5 -> 1 | I5: =I4+1 -> 53 | J5: SHELTER | K5: ='53'!C36 -> 26 | L5: =K5/K5 -> 1
A6: =A5+1 -> 3 | B6: FLOW METER | C6: ='3'!D415 -> 383 | D6: =C6/C6 -> 1 | E6: =E5+1 -> 28 | F6: RECIPROCATING PUMP | G6: ='28'!D50 -> 31 | H6: =G6/G6 -> 1 | K6: =SUM(K4:K5) -> 40 | L6: =AVERAGE(L4:L5) -> 1
A7: =A6+1 -> 4 | B7: PRESSURE INSTRUMENT | C7: ='4'!D359 -> 323 | D7: =C7/C7 -> 1 | E7: =E6+1 -> 29 | F7: CENTRIFUGAL PUMP | G7: ='29'!D140 -> 121 | H7: =G7/G7 -> 1
A8: =A7+1 -> 5 | B8: PRESSURE GAUGE | C8: ='5'!D720 -> 683 | D8: =C8/C8 -> 1 | E8: =E7+1 -> 30 | F8: BLOWER | G8: ='30'!D40 -> 19 | H8: =G8/G8 -> 1
A9: =A8+1 -> 6 | B9: TEMPERATURE INSTRUMENT | C9: ='6'!D501 -> 468 | D9: =C9/C9 -> 1 | E9: =E8+1 -> 31 | F9: COMPRESSOR | G9: ='31'!D35 -> 20 | H9: =G9/G9 -> 1
A10: =A9+1 -> 7 | B10: TEMPERATURE GAUGE | C10: ='7'!D212 -> 192 | D10: =C10/C10 -> 1 | E10: =E9+1 -> 32 | F10: Package Unit | G10: ='32'!D67 -> 50 | H10: =G10/G10 -> 1
A11: =A10+1 -> 8 | B11: LEVEL INSTRUMENT | C11: ='8'!D327 -> 298 | D11: =C11/C11 -> 1 | E11: =E10+1 -> 33 | F11: SEPARATOR | G11: ='33'!D38 -> 20 | H11: =G11/G11 -> 1
A12: =A11+1 -> 9 | B12: LEVEL GAUGE | C12: ='9'!D200 -> 176 | D12: =C12/C12 -> 1 | E12: =E11+1 -> 34 | F12: TANK | G12: ='34'!D93 -> 77 | H12: =G12/G12 -> 1
A13: =A12+1 -> 10 | B13: ANALYZER | C13: ='10'!F57 -> 37 | D13: =C13/C13 -> 1 | E13: =E12+1 -> 35 | F13: DRUM | G13: ='35'!D117 -> 98 | H13: =G13/G13 -> 1
A14: =A13+1 -> 11 | B14: MISCELLENOUS (GD,VS,HY,HC,PY,TY, RD) | C14: ='11'!F125 -> 114 | D14: =C14/C14 -> 1 | E14: =E13+1 -> 36 | F14: TOWER | G14: ='36'!D50 -> 34 | H14: =G14/G14 -> 1
A15: =A14+1 -> 12 | B15: MOTOR | C15: ='12'!C470 -> 435 | D15: =C15/C15 -> 1 | E15: =E14+1 -> 37 | F15: REAKTOR | G15: ='37'!D33 -> 13 | H15: =G15/G15 -> 1
A16: =A15+1 -> 13 | B16: TRANSFORMER | C16: ='13'!C21 -> 10 | D16: =C16/C16 -> 1 | E16: =E15+1 -> 38 | F16: HEAT EXCHANGER (STHE, PHE) | G16: ='38'!D178 -> 158 | H16: =G16/G16 -> 1
A17: =A16+1 -> 14 | B17: BATTERY | C17: ='14'!C278 -> 268 | D17: =C17/C17 -> 1 | E17: =E16+1 -> 39 | F17: FILTER | G17: ='39'!D63 -> 45 | H17: =G17/G17 -> 1
A18: =A17+1 -> 15 | B18: PANEL LISTRIK | C18: ='15'!C55 -> 46 | D18: =C18/C18 -> 1 | E18: =E17+1 -> 40 | F18: CANNED PUMP | G18: ='40'!D142 -> 123 | H18: =G18/G18 -> 1
A19: =A18+1 -> 16 | B19: PANEL INSTRUMENT | C19: ='16'!C60 -> 36 | D19: =C19/C19 -> 1 | E19: 41 | F19: EJECTOR | G19: ='41'!D29 -> 4 | H19: =G19/G19 -> 1
A20: =A19+1 -> 17 | B20: RECEIPTACLE | C20: ='17'!C123 -> 114 | D20: =C20/C20 -> 1 | E20: 42 | F20: SAFETY VALVE | G20: ='42'!D196 -> 167 | H20: =G20/G20 -> 1
A21: =A20+1 -> 18 | B21: PAGING SYSTEM | C21: ='18'!E43 -> 34 | D21: =C21/C21 -> 1 | E21: 43 | F21: STEAM TRAP | G21: ='43'!D41 -> 27 | H21: =G21/G21 -> 1
A22: =A21+1 -> 19 | B22: AIR CONDITIONING | C22: ='19'!B65 -> 55 | D22: =C22/C22 -> 1 | E22: 44 | F22: STRAINER | G22: ='44'!D73 -> 62 | H22: =G22/G22 -> 1
A23: =A22+1 -> 20 | B23: FASILITAS (SNORKLIFT, PENGUSIR TIKUS, PABX) | C23: ='20'!D40 -> 31 | D23: =C23/C23 -> 1 | E23: 45 | F23: STATIC MIXER | G23: ='45'!D40 -> 9 | H23: =G23/G23 -> 1
A24: =A23+1 -> 21 | B24: CATHODIC PROTECTION | C24: ='21'!C35 -> 26 | D24: =C24/C24 -> 1 | E24: 46 | F24: HEAT EXCHANGER (AIR FIN COOLER) | G24: ='46'!D70 -> 47 | H24: =G24/G24 -> 1
A25: =A24+1 -> 22 | B25: GROUNDING | C25: ='22'!C83 -> 73 | D25: =C25/C25 -> 1 | E25: 47 | F25: PIPING LIST SYN GAS | G25: ='47'!B508 -> 499 | H25: =G25/G25 -> 1
A26: =A25+1 -> 23 | B26: JUNCTION BOX | C26: ='23'!C132 -> 122 | D26: =C26/C26 -> 1 | E26: 47-1 | F26: VALVE LIST SYN GAS | G26: ='47-1'!A814 -> 520 | H26: ='47-1'!F815 -> 0.99617347
A27: =A26+1 -> 24 | B27: CUBICLE | C27: ='24'!G356 -> 335 | D27: =C27/C27 -> 1 | E27: 48 | F27: PIPING LIST OCTANOL | G27: ='48'!C2087 -> 2078 | H27: =G27/2078 -> 1
A28: =A27+1 -> 25 | B28: PLC & SCADA | C28: ='25'!D24 -> 12 | D28: =C28/C28 -> 1 | E28: 48-1 | F28: VALVE LIST OCTANOL | G28: ='48-1'!E2199 -> 556 | H28: ='48-1'!C2205 -> 0.9985563
A29: 25-1 | B29: BREATHER VALVE | C29: ='25-1'!B73 -> 43 | D29: =C29/C29 -> 1 | E29: 49 | F29: PIPING LIST UTILITY | G29: ='49'!A429 -> 420 | H29: =G29/G29 -> 1
A30: 25-2 | B30: SWITCHGEAR 20KV & 6.3 KV | C30: ='25-2'!D40 -> 31 | D30: =C30/C30 -> 1 | E30: 49-1 | F30: VALVE LIST UTILITY | G30: ='49-1'!I629 -> 419 | H30: ='49-1'!J629 -> 0.99761905
A31: 25-3 | B31: PERALATAN LABORAT | C31: ='25-3'!D32 -> 22 | D31: =C31/C31 -> 1 | E31: 50 | F31: PIPING LIST CO2 GAS | G31: ='50'!A42 -> 33 | H31: =G31/G31 -> 1
A32: 25-4 | B32: ROAD LIGHTING | C32: ='25-4'!D107 -> 97 | D32: =C32/C32 -> 1 | E32: 50-1 | F32: VALVE LIST CO2 GAS | G32: ='50-1'!A45 -> 33 | H32: =G32/G32 -> 1
A33: 25-5 | B33: ALAT UKUR | C33: ='25-5'!A60 -> 39 | D33: =C33/C33 -> 1 | E33: 51 | F33: PIPING LIST CO2 LIQUID | G33: ='51'!A114 -> 105 | H33: =G33/G33 -> 1
A34: 25-6 | B34: CABLE | C34: ='25-6'!A1507 -> 1448 | D34: ='25-6'!E1507/C34 -> 0.99585635 | E34: 51-1 | F34: VALVE LIST CO2 LIQUID | G34: ='51-1'!A130 -> 105 | H34: =G34/G34 -> 1
B35: Total equipment | C35: =SUM(C4:C34) -> 6731 | D35: =AVERAGE(D32:D34) -> 0.99861878
B36: Total progress terecord | C36: =D30+H29 -> 2 | G36: =SUM(G4:G35) -> 5923 | H36: =AVERAGE(H25:H34) -> 0.99923488 | J36: Total Progress : | L36: =AVERAGE(D35,H36,L6) -> 0.99928456
B37: Note:
B38: Criteria= C : Critical; S : Safety; E : Environment
B39: Criteria Level= *: 1 criteria, **: 2 Criteria, ***: 3 Criteria
B40: Criteria Point= 5: *, 25: **, 125: ***
A42: 1 | B42: 5
...

Sheet 53
D1: SHELTER
A3: NO | B3: Code | C3: NAME | D3: LOCATION | E3: Area | F3: SIZE | G3: Category | I3: COMPLEX GRADE | J3: REMARK
C4: SHELTER | G4: Score | H4: Grade
A6: 1 | C6: Shelter RO | D6: Gate 2 | E6: Utility
A7: =A6+1 -> 2 | C7: Shelter Chemical | D7: Gate 2 | E7: Utility
A8: =A7+1 -> 3 | C8: Shelter Maintenance | D8: Gate 2 | E8: Utility
A9: =A8+1 -> 4 | C9: Waste Shelter ( B3 ) | D9: Gate 2 | E9: Utility
A10: =A9+1 -> 5 | C10: Foam trailer shelter | D10: Gate 2 | E10: Utility
A11: =A10+1 -> 6 | C11: Shelter RO SWWT | D11: Gate 2 | E11: Utility
A12: =A11+1 -> 7 | C12: Shelter H-923 | D12: Gate 2 | E12: Utility
A13: =A12+1 -> 8 | C13: Shelter H-922 | D13: Gate 2 | E13: Utility
A14: =A13+1 -> 9 | C14: Shelter N2 Generator | D14: Gate 2 | E14: Utility
A15: =A14+1 -> 10 | C15: Shelter Chiller & comp udara | D15: Gate 2 | E15: Utility
A16: =A15+1 -> 11 | C16: Shelter Inject Chemical cooling tower | D16: Gate 2 | E16: Utility
A17: =A16+1 -> 12 | C17: Shelter C-412, C-150 | D17: Gate 2 | E17: Octanol
A18: =A17+1 -> 13 | C18: Shelter D-102 | D18: Gate 2 | E18: Octanol
... A31: =A30+1 -> 26 | C31: POS-6 Shelter | D31: Gate 2 | E31: -
D32: Gate 2 | E32: -
A36: Total Asset : | C36: =COUNTA(C6:C34) -> 26

Sheet 52
D1: BUILDING / GEDUNG
A3: NO | B3: Code | C3: NAME | D3: LOCATION | E3: SIZE | F3: Category | H3: COMPLEX GRADE | I3: REMARK
C4: Building / Gedung | F4: Score | G4: Grade
A6: 1 | C6: Maintenance | D6: Gate 2
A7: 2 | C7: Safety | D7: Gate 2
A8: 3 | C8: Laboratory | D8: Gate 2
A9: 4 | C9: EDG | D9: Gate 2
A10: 5 | C10: Main Subtation | D10: Gate 2
A11: 6 | C11: MCR | D11: Gate 2
A12: 7 | C12: Office produksi | D12: Gate 2
A13: 8 | C13: A/C Room | D13: Gate 2
A14: 9 | C14: Rack room | D14: Gate 2
A15: 10 | C15: A/C Room | D15: Gate 2
A16: 11 | C16: LSS | D16: Gate 2
A17: 12 | C17: Analyzer room Octanol | D17: Gate 2
... A19: 14 | C19: MCC Room | D19: Gate 2
F22: =IF(ISERROR(INDEX(data,MATCH(LEN(H22),item,0),2))," ",INDEX(data,MATCH(LEN(H22),item,0),2))
A24: Total Asset : | C24: =COUNTA(C6:C21) -> 14

Sheet 51-1
C1: EQUIPMENT LIST | F1: Document No. | I1: : MNTC-ME
F2: Revision | I2: : 0
F3: Date of issue | I3: : 2025
A4: PT. PETRO OXO NUSANTARA | F4: Page | I4: :
A5: VALVE LIST CO2 LIQUID
A7: NO | B7: Code | C7: Line Number piping + accecories | D7: Diameter | E7: SCH | F7: Valve | G7: Material | H7: Remark
A9: CO2 Liquid
A10: 1 | B10: 510362 | C10: CG-B365R-A-P36128
A11: =A10+1 -> 2 | B11: 510363 | C11: CG-B365R-A-P36146
A12: =A11+1 -> 3 | B12: 510364 | C12: CG-B365R-A-P36149
A13: =A12+1 -> 4 | B13: 510365 | C13: CG-E150-A-P11502
A14: =A13+1 -> 5 | B14: 510366 | C14: CG-E150-A-P11502
A15: =A14+1 -> 6 | B15: 510367 | C15: CG-E150-A-P12301
A16: =A15+1 -> 7 | B16: 510368 | C16: CG-E150-A-P12302 | D16: 6" | E16: 150 | F16: BV2 | G16: SS316 | H16: Butterfly Valve
D17: 1" | E17: - | F17: BLV1 | G17: SS | H17: Ball Valve
A18: =A16+1 -> 8 | B18: 510369 | C18: CG-E150-A-P12302 | D18: 1/2" | E18: - | F18: BLV1 | H18: Ball Valve
A19: =A18+1 -> 9 | B19: 510374 | C19: CG-E435-A-P11607 | D19: 1 | E19: - | F19: BLV1 | G19: SS | H19: Ball Valve
D20: 1 | E20: 300 | F20: CV1 | G20: SS | H20: Check Valve
D21: 1/2 | E21: - | F21: BLV1 | G21: SS | H21: Ball Valve
A22: =A19+1 -> 10 | B22: 510375 | C22: CG-E435-A-P36127 | D22: 1 | E22: - | F22: BLV1 | G22: SS | H22: Ball Valve
D23: 1/2 | E23: - | F23: BLV1 | G23: SS | H23: Ball Valve
A24: =A22+1 -> 11 | B24: 510376 | C24: CG-E150-A-P67901 | D24: 1/2 | E24: - | F24: NV2 | H24: Needle Valve
A25: =A24+1 -> 12 | B25: 510377 | C25: CG-E150-A-P67901 | D25: 1/2 | E25: - | F25: NV4 | H25: Needle Valve
A26: =A25+1 -> 13 | B26: 510378 | C26: CG-E150-A-P67901 | D26: 1/2 | E26: - | F26: NV3 | H26: Needle Valve
A27: =A26+1 -> 14 | B27: 510379 | C27: CG-E150-A-P67901 | D27: 1/2 | E27: - | F27: NV3 | H27: Needle Valve
A28: =A27+1 -> 15 | B28: 510380 | C28: CG-F435-A-P20138 | D28: 1 | E28: - | F28: BLV1 | G28: SS | H28: Ball Valve
A29: =A28+1 -> 16 | B29: 510381 | C29: CG-F435-A-P20138 | D29: 2 | E29: - | F29: BLV2 | G29: SS | H29: Ball Valve
A30: =A29+1 -> 17 | B30: 510382 | C30: CG-F435-A-P33531
A31: =A30+1 -> 18 | B31: 510383 | C31: CL-B365R-A-P37315
A32: =A31+1 -> 19 | B32: 510384 | C32: CW-A150-A-P11420
A33: =A32+1 -> 20 | B33: 510385 | C33: CW-A150-A-P11226
A34: =A33+1 -> 21 | B34: 510386 | C34: CW-A150-A- P50102 | D34: 14 | E34: 150 | F34: BV1 | G34: SS316 | H34: Butterfly Valve
D35: 1 | F35: BLV1 | G35: SS | H35: Ball Valve
D36: 1/2 | F36: BLV1 | H36: Ball Valve
A37: =A34+1 -> 22 | B37: 510387 | C37: CO-A150-A-P10114
A38: =A37+1 -> 23 | B38: 510388 | C38: CW-A150-A- P50106
A39: =A38+1 -> 24 | B39: 510389 | C39: CW-A150-A- P50108
A40: =A39+1 -> 25 | B40: 510390 | C40: CW-A150-A-P50113
A41: =A40+1 -> 26 | B41: 510391 | C41: CW-A150-A-P10116
A42: =A41+1 -> 27 | B42: 510392 | C42: CW-A150-A- P40123
...

Sheet 51
C1: ASSET LIST | G1: Document No. | J1: : MNTC-ME
G2: Revision | J2: : 0
G3: Date of issue | J3: : 2025
A4: PT. PETRO OXO NUSANTARA | G4: Page | J4: :
A5: PIPING LIST CO2 LIQUID
A7: No | B7: Line No. | C7: Size | D7: Service | E7: Fluid | F7: Material | G7: Insulation | H7: PAGE NO. | I7: Drawing | J7: Pipe length ( mm )
A8: 1 | B8: CG-B365R-A-P36128 | C8: 3" | D8: Carbon Dioxide Gaseous | E8: Gas | F8: CS low temp | H8: 510362 | I8: =HYPERLINK("\\CAD-PC\1Data\3.Documentation\Isometric DWG\Line List & Data Inspeksi\29. Isometric CO2 Liquid\" & H8 &" A" & ".pdf", "Drawing") -> Drawing
A9: =A8+1 -> 2 | B9: CG-B365R-A-P36146 | C9: 1" | D9: Carbon Dioxide Gaseous | E9: Gas | F9: CS low temp | H9: 510363 | I9: =HYPERLINK("\\CAD-PC\1Data\3.Documentation\Isometric DWG\Line List & Data Inspeksi\29. Isometric CO2 Liquid\" & H9 &" A" & ".pdf", "Drawing") -> Drawing
A10: =A9+1 -> 3 | B10: CG-B365R-A-P36149 | C10: 2 | D10: Carbon Dioxide Gaseous | E10: Gas | F10: CS low temp | H10: 510364 | I10: =HYPERLINK("\\CAD-PC\1Data\3.Documentation\Isometric DWG\Line List & Data Inspeksi\29. Isometric CO2 Liquid\" & H10 &" A" & ".pdf", "Drawing") -> Drawing
A11: =A10+1 -> 4 | B11: CG-E150-A-P11502 | C11: 12 | D11: Carbon Dioxide Gaseous | E11: Gas | F11: SS304 | H11: 510365 | I11: =HYPERLINK("\\CAD-PC\1Data\3.Documentation\Isometric DWG\Line List & Data Inspeksi\29. Isometric CO2 Liquid\" & H11 &" A" & ".pdf", "Drawing") -> Drawing
A12: =A11+1 -> 5 | B12: CG-E150-A-P11502 | C12: 12 | D12: Carbon Dioxide Gaseous | E12: Gas | F12: SS304 | H12: 510366 | I12: =HYPERLINK("\\CAD-PC\1Data\3.Documentation\Isometric DWG\Line List & Data Inspeksi\29. Isometric CO2 Liquid\" & H12 &" A" & ".pdf", "Drawing") -> Drawing
A13: =A12+1 -> 6 | B13: CG-E150-A-P12301 | C13: 10 | D13: Carbon Dioxide Gaseous | E13: Gas | F13: SS304 | H13: 510367 | I13: =HYPERLINK("\\CAD-PC\1Data\3.Documentation\Isometric DWG\Line List & Data Inspeksi\29. Isometric CO2 Liquid\" & H13 &" A" & ".pdf", "Drawing") -> Drawing
A14: =A13+1 -> 7 | B14: CG-E150-A-P12302 | C14: 10 | D14: Carbon Dioxide Gaseous | E14: Gas | F14: SS304 | H14: 510368 | I14: =HYPERLINK("\\CAD-PC\1Data\3.Documentation\Isometric DWG\Line List & Data Inspeksi\29. Isometric CO2 Liquid\" & H14 &" A" & ".pdf", "Drawing") -> Drawing
A15: =A14+1 -> 8 | B15: CG-E150-A-P12302 | C15: 10 | D15: Carbon Dioxide Gaseous | E15: Gas | F15: SS304 | H15: 510369 | I15: =HYPERLINK("\\CAD-PC\1Data\3.Documentation\Isometric DWG\Line List & Data Inspeksi\29. Isometric CO2 Liquid\" & H15 &" A" & ".pdf", "Drawing") -> Drawing
A16: =A15+1 -> 9 | B16: CG-E435-A-P11607 | C16: 1 | D16: Carbon Dioxide Gaseous | E16: Gas | F16: CS | H16: 510374 | I16: =HYPERLINK("\\CAD-PC\1Data\3.Documentation\Isometric DWG\Line List & Data Inspeksi\29. Isometric CO2 Liquid\" & H16 &" A" & ".pdf", "Drawing") -> Drawing
A17: =A16+1 -> 10 | B17: CG-E435-A-P36127 | C17: 2 | D17: Carbon Dioxide Gaseous | E17: Gas | F17: CS | H17: 510375 | I17: =HYPERLINK("\\CAD-PC\1Data\3.Documentation\Isometric DWG\Line List & Data Inspeksi\29. Isometric CO2 Liquid\" & H17 &" A" & ".pdf", "Drawing") -> Drawing
A18: =A17+1 -> 11 | B18: CG-E150-A-P67901 | C18: 1 | D18: Carbon Dioxide Gaseous | E18: Gas | F18: SS304 | H18: 510376 | I18: =HYPERLINK("\\CAD-PC\1Data\3.Documentation\Isometric DWG\Line List & Data Inspeksi\29. Isometric CO2 Liquid\" & H18 &" A" & ".pdf", "Drawing") -> Drawing
A19: =A18+1 -> 12 | B19: CG-E150-A-P67901 | C19: 1 | D19: Carbon Dioxide Gaseous | E19: Gas | F19: SS304 | H19: 510377 | I19: =HYPERLINK("\\CAD-PC\1Data\3.Documentation\Isometric DWG\Line List & Data Inspeksi\29. Isometric CO2 Liquid\" & H19 &" A" & ".pdf", "Drawing") -> Drawing
A20: =A19+1 -> 13 | B20: CG-E150-A-P67901 | D20: Carbon Dioxide Gaseous | E20: Gas | F20: SS304 | H20: 510378 | I20: =HYPERLINK("\\CAD-PC\1Data\3.Documentation\Isometric DWG\Line List & Data Inspeksi\29. Isometric CO2 Liquid\" & H20 &" A" & ".pdf", "Drawing") -> Drawing
A21: =A20+1 -> 14 | B21: CG-E150-A-P67901 | D21: Carbon Dioxide Gaseous | E21: Gas | F21: SS304 | H21: 510379 | I21: =HYPERLINK("\\CAD-PC\1Data\3.Documentation\Isometric DWG\Line List & Data Inspeksi\29. Isometric CO2 Liquid\" & H21 &" A" & ".pdf", "Drawing") -> Drawing
A22: =A21+1 -> 15 | B22: CG-F435-A-P20138 | D22: Carbon Dioxide Gaseous | E22: Gas | F22: CS | H22: 510380 | I22: =HYPERLINK("\\CAD-PC\1Data\3.Documentation\Isometric DWG\Line List & Data Inspeksi\29. Isometric CO2 Liquid\" & H22 &" A" & ".pdf", "Drawing") -> Drawing
A23: =A22+1 -> 16 | B23: CG-F435-A-P20138 | D23: Carbon Dioxide Gaseous | E23: Gas | F23: CS | H23: 510381 | I23: =HYPERLINK("\\CAD-PC\1Data\3.Documentation\Isometric DWG\Line List & Data Inspeksi\29. Isometric CO2 Liquid\" & H23 &" A" & ".pdf", "Drawing") -> Drawing
A24: =A23+1 -> 17 | B24: CG-F435-A-P33531 | D24: Carbon Dioxide Gaseous | E24: Gas | F24: CS | H24: 510382 | I24: =HYPERLINK("\\CAD-PC\1Data\3.Documentation\Isometric DWG\Line List & Data Inspeksi\29. Isometric CO2 Liquid\" & H24 &" A" & ".pdf", "Drawing") -> Drawing
A25: =A24+1 -> 18 | B25: CL-B365R-A-P37315 | D25: Carbon Dioxide Liquid | E25: Liquid | F25: CS low temp | H25: 510383 | I25: =HYPERLINK("\\CAD-PC\1Data\3.Documentation\Isometric DWG\Line List & Data Inspeksi\29. Isometric CO2 Liquid\" & H25 &" A" & ".pdf", "Drawing") -> Drawing
A26: =A25+1 -> 19 | B26: CW-A150-A-P11420 | D26: Cooling Water | E26: Water | F26: CS | H26: 510384 | I26: =HYPERLINK("\\CAD-PC\1Data\3.Documentation\Isometric DWG\Line List & Data Inspeksi\29. Isometric CO2 Liquid\" & H26 &" A" & ".pdf", "Drawing") -> Drawing
A27: =A26+1 -> 20 | B27: CW-A150-A-P11226 | D27: Cooling Water | E27: Water | F27: CS | H27: 510385 | I27: =HYPERLINK("\\CAD-PC\1Data\3.Documentation\Isometric DWG\Line List & Data Inspeksi\29. Isometric CO2 Liquid\" & H27 &" A" & ".pdf", "Drawing") -> Drawing
A28: =A27+1 -> 21 | B28: CW-A150-A- P50102 | D28: Cooling Water | E28: Water | F28: CS | H28: 510386 | I28: =HYPERLINK("\\CAD-PC\1Data\3.Documentation\Isometric DWG\Line List & Data Inspeksi\29. Isometric CO2 Liquid\" & H28 &" A" & ".pdf", "Drawing") -> Drawing
A29: =A28+1 -> 22 | B29: CO-A150-A-P10114 | D29: Condensate | E29: Water | F29: CS | H29: 510387 | I29: =HYPERLINK("\\CAD-PC\1Data\3.Documentation\Isometric DWG\Line List & Data Inspeksi\29. Isometric CO2 Liquid\" & H29 &" A" & ".pdf", "Drawing") -> Drawing
A30: =A29+1 -> 23 | B30: CW-A150-A- P50106 | D30: Cooling Water | E30: Water | F30: CS | H30: 510388 | I30: =HYPERLINK("\\CAD-PC\1Data\3.Documentation\Isometric DWG\Line List & Data Inspeksi\29. Isometric CO2 Liquid\" & H30 &" A" & ".pdf", "Drawing") -> Drawing
A31: =A30+1 -> 24 | B31: CW-A150-A- P50108 | D31: Cooling Water | E31: Water | F31: CS | H31: 510389 | I31: =HYPERLINK("\\CAD-PC\1Data\3.Documentation\Isometric DWG\Line List & Data Inspeksi\29. Isometric CO2 Liquid\" & H31 &" A" & ".pdf", "Drawing") -> Drawing
... A95: =A94+1 -> 88 | B95: RG-B365R-A-P38145 | D95: Refrigerant Gaseous | E95: Gas | F95: CS low temp | H95: 510457 | I95: =HYPERLINK("\\CAD-PC\1Data\3.Documentation\Isometric DWG\Line List & Data Inspeksi\29. Isometric CO2 Liquid\" & H95 &" A" & ".pdf", "Drawing") -> Drawing
A96: =A95+1 -> 89 | B96: RG-B365R-A-P47114 | C96: 2" | D96: Refrigerant Gaseous | E96: Gas | F96: CS low temp | H96: 510458 | I96: =HYPERLINK("\\CAD-PC\1Data\3.Documentation\Isometric DWG\Line List & Data Inspeksi\29. Isometric CO2 Liquid\" & H96 &" A" & ".pdf", "Drawing") -> Drawing
A97: =A96+1 -> 90 | B97: RL-B365R-A-P47108 | D97: Refrigerant Liquid | E97: Liquid | F97: CS low temp | H97: 510459 | I97: =HYPERLINK("\\CAD-PC\1Data\3.Documentation\Isometric DWG\Line List & Data Inspeksi\29. Isometric CO2 Liquid\" & H97 &" A" & ".pdf", "Drawing") -> Drawing
A98: =A97+1 -> 91 | B98: RG-A450-A-P40119 | D98: Refrigerant Gaseous | E98: Gas | F98: CS | H98: 510460 | I98: =HYPERLINK("\\CAD-PC\1Data\3.Documentation\Isometric DWG\Line List & Data Inspeksi\29. Isometric CO2 Liquid\" & H98 &" A" & ".pdf", "Drawing") -> Drawing
A99: =A98+1 -> 92 | B99: RW-E150-A-P11421 | D99: Raw Water | E99: Water | F99: SS304 | H99: 510462 | I99: =HYPERLINK("\\CAD-PC\1Data\3.Documentation\Isometric DWG\Line List & Data Inspeksi\29. Isometric CO2 Liquid\" & H99 &" A" & ".pdf", "Drawing") -> Drawing
A100: =A99+1 -> 93 | B100: RW-E150-A-P12303 | D100: Raw Water | E100: Water | F100: SS304 | H100: 510464 | I100: =HYPERLINK("\\CAD-PC\1Data\3.Documentation\Isometric DWG\Line List & Data Inspeksi\29. Isometric CO2 Liquid\" & H100 &" A" & ".pdf", "Drawing") -> Drawing
A101: =A100+1 -> 94 | B101: RW-E150-A-P12303 | D101: Raw Water | E101: Water | F101: SS304 | H101: 510465 | I101: =HYPERLINK("\\CAD-PC\1Data\3.Documentation\Isometric DWG\Line List & Data Inspeksi\29. Isometric CO2 Liquid\" & H101 &" A" & ".pdf", "Drawing") -> Drawing
A102: =A101+1 -> 95 | B102: SC-F150-A-P11208 | D102: Sodium Carbonate | E102: Chemical Solution | F102: SS316 | H102: 510466 | I102: =HYPERLINK("\\CAD-PC\1Data\3.Documentation\Isometric DWG\Line List & Data Inspeksi\29. Isometric CO2 Liquid\" & H102 &" A" & ".pdf", "Drawing") -> Drawing
A103: =A102+1 -> 96 | B103: SC-F150-A-P11203 | D103: Sodium Carbonate | E103: Chemical Solution | F103: SS316 | H103: 510467 | I103: =HYPERLINK("\\CAD-PC\1Data\3.Documentation\Isometric DWG\Line List & Data Inspeksi\29. Isometric CO2 Liquid\" & H103 &" A" & ".pdf", "Drawing") -> Drawing
A104: =A103+1 -> 97 | B104: SC-F150-A-P11204 | D104: Sodium Carbonate | E104: Chemical Solution | F104: SS316 | H104: 510468 | I104: =HYPERLINK("\\CAD-PC\1Data\3.Documentation\Isometric DWG\Line List & Data Inspeksi\29. Isometric CO2 Liquid\" & H104 &" A" & ".pdf", "Drawing") -> Drawing
...

Sheet 50-1
C1: EQUIPMENT LIST | F1: Document No. | I1: : MNTC-ME
F2: Revision | I2: : 0
F3: Date of issue | I3: : 2025
A4: PT. PETRO OXO NUSANTARA | F4: Page | I4: :
A5: VALVE LIST CO2 GAS
A7: NO | B7: Code | C7: Line Number piping + accecories | D7: Diameter | E7: SCH | F7: Valve | G7: Material | H7: Remark
A9: CO2 Gas
A10: 1 | B10: 134542 | C10: CG-E150A-P11502-1 | D10: 4" | E10: 10S | F10: CV1
A11: =A10+1 -> 2 | B11: 134543 | C11: CG-E150A-P12301
A12: =A11+1 -> 3 | B12: 134544 | C12: CG-E150A-P12302 | D12: 6" | E12: 10S | F12: BV1 | H12: Butterfly Valve
A13: =A12+1 -> 4 | B13: 134545 | C13: CO-A150A-P10305-1
A14: =A13+1 -> 5 | B14: 134546 | C14: CW-A150A-P50302-1 1/2
A15: =A14+1 -> 6 | B15: 134547 | C15: CW-A150A-P50302-1 2/2 | D15: 1/2" | E15: - | F15: BLV1 | H15: Ball Valve
A16: =A15+1 -> 7 | B16: 134548 | C16: CW-A150A-P50302-2
A17: =A16+1 -> 8 | B17: 134549 | C17: FG-A150A-P11201 | D17: 1/2" | E17: - | F17: BLV1 | H17: Ball Valve
A18: =A17+1 -> 9 | B18: 134550 | C18: FG-E150A-P11202 | D18: 1/2" | E18: - | F18: NDV1, BLV1 | H18: Needle & Ball Valve
A19: =A18+1 -> 10 | B19: 134551 | C19: FG-E150A-P11302 | D19: 1/2" | E19: - | F19: BLV2 | H19: Ball Valve
A20: =A19+1 -> 11 | B20: 134552 | C20: HV-11203-01 | D20: 1/2" | E20: - | F20: BLV1 | H20: Ball Valve
A21: =A20+1 -> 12 | B21: 134553 | C21: HV-11558-35 | D21: 1/2" | E21: - | F21: NDV1 | H21: Needle Valve
A22: =A21+1 -> 13 | B22: 134554 | C22: ME-E150A-P11501-3
A23: =A22+1 -> 14 | B23: 134555 | C23: ME-E150A-P10302 | D23: 1/2" | E23: - | F23: BLV1 | H23: Ball Valve
A24: =A23+1 -> 15 | B24: 134556 | C24: ME-E150A-P10402
A25: =A24+1 -> 16 | B25: 134557 | C25: ME-E150A-P10410-1
A26: =A25+1 -> 17 | B26: 134558 | C26: ME-E150A-P10410-2
A27: =A26+1 -> 18 | B27: 134559 | C27: ME-E150A-P11402-1 | D27: 1/2" | E27: - | F27: BLV1 | H27: Ball Valve
A28: =A27+1 -> 19 | B28: 134572 | C28: ME-E150A-P11403-2
A29: =A28+1 -> 20 | B29: 134835 | C29: ME-E150A-P11503-1 | D29: 1/2" | E29: - | F29: BLV1 | H29: Ball Valve
A30: =A29+1 -> 21 | B30: 134836 | C30: ME-E150A-P11504
A31: =A30+1 -> 22 | B31: 134837 | C31: PW-E150A-P10405
A32: =A31+1 -> 23 | B32: 134838 | C32: PW-E150A-P11204-1
A33: =A32+1 -> 24 | B33: 134839 | C33: PW-E150A-P11204-3
A34: =A33+1 -> 25 | B34: 134840 | C34: PW-E150A-P11208 | D34: 1" | E34: - | F34: BLV1 | H34: Ball Valve
A35: =A34+1 -> 26 | B35: 134841 | C35: PW-E150A-P11404-1
A36: =A35+1 -> 27 | B36: 134842 | C36: PW-E150A-P11405
A37: =A36+1 -> 28 | B37: 134843 | C37: PW-E150A-P11505-2
A38: =A37+1 -> 29 | B38: 134844 | C38: PW-E150A-P11558-1
A39: =A38+1 -> 30 | B39: 134845 | C39: PW-E150A-P11558 | D39: 1" | E39: - | F39: BLV1 | H39: Ball Valve
A40: =A39+1 -> 31 | B40: 134846 | C40: RW-E150A-P12303 | D40: 1" | E40: - | F40: BLV1,CV1 | H40: Ball Valve, Check Valve
D41: 1/2" | E41: - | F41: NDV1, BLV1 | H41: Needle & Ball Valve
A42: =A40+1 -> 32 | B42: 134847 | C42: SC-E150A-P11203 | D42: 1/2" | E42: - | F42: CV1 | G42: PVC | H42: Check Valve
...

Sheet 50
C1: ASSET LIST | G1: Document No. | J1: : MNTC-ME
G2: Revision | J2: : 0
G3: Date of issue | J3: : 2025
A4: PT. PETRO OXO NUSANTARA | G4: Page | J4: :
A5: PIPING LIST CO2 GAS
A7: No | B7: Line No. | C7: Size | D7: Service | E7: Fluid | F7: Material | G7: Insulation | H7: PAGE NO. | I7: Drawing | J7: Pipe length ( mm )
A8: 1 | B8: CG-E150A-P11502-1 | D8: Carbon Dioxide Gaseous | E8: Gas | F8: SS304 | H8: 134542 | I8: =HYPERLINK("\\CAD-PC\1Data\3.Documentation\Isometric DWG\Line List & Data Inspeksi\29. Isometric CO2 Gas\" & H8 & ".pdf", "Drawing") -> Drawing
A9: =A8+1 -> 2 | B9: CG-E150A-P12301 | D9: Carbon Dioxide Gaseous | E9: Gas | F9: SS304 | H9: 134543 | I9: =HYPERLINK("\\CAD-PC\1Data\3.Documentation\Isometric DWG\Line List & Data Inspeksi\29. Isometric CO2 Gas\" & H9 & ".pdf", "Drawing") -> Drawing
A10: =A9+1 -> 3 | B10: CG-E150A-P12302 | D10: Carbon Dioxide Gaseous | E10: Gas | F10: SS304 | H10: 134544 | I10: =HYPERLINK("\\CAD-PC\1Data\3.Documentation\Isometric DWG\Line List & Data Inspeksi\29. Isometric CO2 Gas\" & H10 & ".pdf", "Drawing") -> Drawing
A11: =A10+1 -> 4 | B11: CO-A150A-P10305-1 | D11: Condensate | E11: Water | F11: CS | H11: 134545 | I11: =HYPERLINK("\\CAD-PC\1Data\3.Documentation\Isometric DWG\Line List & Data Inspeksi\29. Isometric CO2 Gas\" & H11 & ".pdf", "Drawing") -> Drawing
A12: =A11+1 -> 5 | B12: CW-A150A-P50302-1 1/2 | D12: Cooling Water | E12: Water | F12: CS | H12: 134546 | I12: =HYPERLINK("\\CAD-PC\1Data\3.Documentation\Isometric DWG\Line List & Data Inspeksi\29. Isometric CO2 Gas\" & H12 & ".pdf", "Drawing") -> Drawing
A13: =A12+1 -> 6 | B13: CW-A150A-P50302-1 2/2 | D13: Cooling Water | E13: Water | F13: CS | H13: 134547 | I13: =HYPERLINK("\\CAD-PC\1Data\3.Documentation\Isometric DWG\Line List & Data Inspeksi\29. Isometric CO2 Gas\" & H13 & ".pdf", "Drawing") -> Drawing
A14: =A13+1 -> 7 | B14: CW-A150A-P50302-2 | D14: Cooling Water | E14: Water | F14: CS | H14: 134548 | I14: =HYPERLINK("\\CAD-PC\1Data\3.Documentation\Isometric DWG\Line List & Data Inspeksi\29. Isometric CO2 Gas\" & H14 & ".pdf", "Drawing") -> Drawing
A15: =A14+1 -> 8 | B15: FG-A150A-P11201 | D15: Flue Gas | E15: Gas | F15: CS | H15: 134549 | I15: =HYPERLINK("\\CAD-PC\1Data\3.Documentation\Isometric DWG\Line List & Data Inspeksi\29. Isometric CO2 Gas\" & H15 & ".pdf", "Drawing") -> Drawing
A16: =A15+1 -> 9 | B16: FG-E150A-P11202 | D16: Flue Gas | E16: Gas | F16: SS304 | H16: 134550 | I16: =HYPERLINK("\\CAD-PC\1Data\3.Documentation\Isometric DWG\Line List & Data Inspeksi\29. Isometric CO2 Gas\" & H16 & ".pdf", "Drawing") -> Drawing
A17: =A16+1 -> 10 | B17: FG-E150A-P11302 | D17: Flue Gas | E17: Gas | F17: SS304 | H17: 134551 | I17: =HYPERLINK("\\CAD-PC\1Data\3.Documentation\Isometric DWG\Line List & Data Inspeksi\29. Isometric CO2 Gas\" & H17 & ".pdf", "Drawing") -> Drawing
A18: =A17+1 -> 11 | B18: HV-11203-01 | H18: 134552 | I18: =HYPERLINK("\\CAD-PC\1Data\3.Documentation\Isometric DWG\Line List & Data Inspeksi\29. Isometric CO2 Gas\" & H18 & ".pdf", "Drawing") -> Drawing
A19: =A18+1 -> 12 | B19: HV-11558-35 | H19: 134553 | I19: =HYPERLINK("\\CAD-PC\1Data\3.Documentation\Isometric DWG\Line List & Data Inspeksi\29. Isometric CO2 Gas\" & H19 & ".pdf", "Drawing") -> Drawing
A20: =A19+1 -> 13 | B20: ME-E150A-P11501-3 | D20: Monoethanolamine Solution | E20: Chemical Solution | F20: SS304 | H20: 134554 | I20: =HYPERLINK("\\CAD-PC\1Data\3.Documentation\Isometric DWG\Line List & Data Inspeksi\29. Isometric CO2 Gas\" & H20 & ".pdf", "Drawing") -> Drawing
A21: =A20+1 -> 14 | B21: ME-E150A-P10302 | D21: Monoethanolamine Solution | E21: Chemical Solution | F21: SS304 | H21: 134555 | I21: =HYPERLINK("\\CAD-PC\1Data\3.Documentation\Isometric DWG\Line List & Data Inspeksi\29. Isometric CO2 Gas\" & H21 & ".pdf", "Drawing") -> Drawing
A22: =A21+1 -> 15 | B22: ME-E150A-P10402 | D22: Monoethanolamine Solution | E22: Chemical Solution | F22: SS304 | H22: 134556 | I22: =HYPERLINK("\\CAD-PC\1Data\3.Documentation\Isometric DWG\Line List & Data Inspeksi\29. Isometric CO2 Gas\" & H22 & ".pdf", "Drawing") -> Drawing
A23: =A22+1 -> 16 | B23: ME-E150A-P10410-1 | D23: Monoethanolamine Solution | E23: Chemical Solution | F23: SS304 | H23: 134557 | I23: =HYPERLINK("\\CAD-PC\1Data\3.Documentation\Isometric DWG\Line List & Data Inspeksi\29. Isometric CO2 Gas\" & H23 & ".pdf", "Drawing") -> Drawing
A24: =A23+1 -> 17 | B24: ME-E150A-P10410-2 | D24: Monoethanolamine Solution | E24: Chemical Solution | F24: SS304 | H24: 134558 | I24: =HYPERLINK("\\CAD-PC\1Data\3.Documentation\Isometric DWG\Line List & Data Inspeksi\29. Isometric CO2 Gas\" & H24 & ".pdf", "Drawing") -> Drawing
A25: =A24+1 -> 18 | B25: ME-E150A-P11402-1 | D25: Monoethanolamine Solution | E25: Chemical Solution | F25: SS304 | H25: 134559 | I25: =HYPERLINK("\\CAD-PC\1Data\3.Documentation\Isometric DWG\Line List & Data Inspeksi\29. Isometric CO2 Gas\" & H25 & ".pdf", "Drawing") -> Drawing
A26: =A25+1 -> 19 | B26: ME-E150A-P11403-2 | D26: Monoethanolamine Solution | E26: Chemical Solution | F26: SS304 | H26: 134572 | I26: =HYPERLINK("\\CAD-PC\1Data\3.Documentation\Isometric DWG\Line List & Data Inspeksi\29. Isometric CO2 Gas\" & H26 & ".pdf", "Drawing") -> Drawing
A27: =A26+1 -> 20 | B27: ME-E150A-P11503-1 | D27: Monoethanolamine Solution | E27: Chemical Solution | F27: SS304 | H27: 134835 | I27: =HYPERLINK("\\CAD-PC\1Data\3.Documentation\Isometric DWG\Line List & Data Inspeksi\29. Isometric CO2 Gas\" & H27 & ".pdf", "Drawing") -> Drawing
A28: =A27+1 -> 21 | B28: ME-E150A-P11504 | D28: Monoethanolamine Solution | E28: Chemical Solution | F28: SS304 | H28: 134836 | I28: =HYPERLINK("\\CAD-PC\1Data\3.Documentation\Isometric DWG\Line List & Data Inspeksi\29. Isometric CO2 Gas\" & H28 & ".pdf", "Drawing") -> Drawing
A29: =A28+1 -> 22 | B29: PW-E150A-P10405 | D29: Process Water | E29: Gas | F29: SS304 | H29: 134837 | I29: =HYPERLINK("\\CAD-PC\1Data\3.Documentation\Isometric DWG\Line List & Data Inspeksi\29. Isometric CO2 Gas\" & H29 & ".pdf", "Drawing") -> Drawing
A30: =A29+1 -> 23 | B30: PW-E150A-P11204-1 | D30: Process Water | E30: Gas | F30: SS304 | H30: 134838 | I30: =HYPERLINK("\\CAD-PC\1Data\3.Documentation\Isometric DWG\Line List & Data Inspeksi\29. Isometric CO2 Gas\" & H30 & ".pdf", "Drawing") -> Drawing
A31: =A30+1 -> 24 | B31: PW-E150A-P11204-3 | D31: Process Water | E31: Gas | F31: SS304 | H31: 134839 | I31: =HYPERLINK("\\CAD-PC\1Data\3.Documentation\Isometric DWG\Line List & Data Inspeksi\29. Isometric CO2 Gas\" & H31 & ".pdf", "Drawing") -> Drawing
... A40: =A39+1 -> 33 | B40: ST-A150A-P10303 | D40: Steam | E40: Steam | F40: CS | H40: 134848 | I40: =HYPERLINK("\\CAD-PC\1Data\3.Documentation\Isometric DWG\Line List & Data Inspeksi\29. Isometric CO2 Gas\" & H40 & ".pdf", "Drawing") -> Drawing
A42: =COUNTA(A8:A40) -> 33

Sheet 49-1
C1: EQUIPMENT LIST | F1: Document No. | H1: : MNTC-ME
F2: Revision | H2: : 0
F3: Date of issue | H3: : 2025
A4: PT. PETRO OXO NUSANTARA | F4: Page | H4: :
A5: VALVE LIST UTILITY
A7: NO | B7: Code | C7: Line Number piping + accecories | D7: Diameter | E7: Rating | F7: Valve | G7: Material | H7: Remark
A9: UTILITY
A10: 1 | B10: G011 | C10: 2"-BBD-9201 -AG 1B-H25 | D10: =LEFT(C10, FIND("""", C10)) -> 2" | I10: 1
A11: 2 | B11: G021 | C11: 2"-BFW-8507-AG 1B-P | D11: =LEFT(C11, FIND("""", C11)) -> 2" | I11: 1
A12: 3 | B12: G022 | C12: 2"-BFW-8505-AG 1B-P (1/2) (2/2) | D12: =LEFT(C12, FIND("""", C12)) -> 2" | E12: 150 | F12: GV | I12: 1
D13: 1/2" | E13: 150 | F13: GV
D14: 2" | E14: 150 | F14: CV
A15: 4 | B15: G023 | C15: 3"-BFW-8503-AG 1 B-P | D15: =LEFT(C15, FIND("""", C15)) -> 3" | E15: 150 | F15: GV | I15: 1
D16: 1/2" | E16: 150 | F16: GV
A17: 5 | B17: G024 | C17: 2-1/2"-BFW-8508- AG1B-P | D17: =LEFT(C17, FIND("""", C17)) -> 2-1/2" | I17: 1
A18: 6 | B18: G025 | C18: 8"-BFW-9201 -AG 1B-H25 | D18: =LEFT(C18, FIND("""", C18)) -> 8" | I18: 1
A19: 7 | B19: G026 | C19: 8"-BFW-9201-AG 1B-H25 | D19: =LEFT(C19, FIND("""", C19)) -> 8" | E19: 150 | F19: GV1 | G19: SS | I19: 1
D20: 3/4" | E20: 150 | F20: GV1 | G20: SS | I20: 1
A21: 8 | B21: G027 | C21: 8"-BFW-9201 -AG 1B-H25 | D21: =LEFT(C21, FIND("""", C21)) -> 8" | E21: 150 | F21: GV1 | I21: 1
A22: 9 | B22: G028 | C22: 4"-BFW-9202-BG4A- H25 | D22: =LEFT(C22, FIND("""", C22)) -> 4" | I22: 1
A23: 10 | B23: G029 | C23: 6"-BFW-9202-BG4A-H25 (1/2) | D23: =LEFT(C23, FIND("""", C23)) -> 6" | E23: 300 | F23: GV1 | I23: 1
A24: 11 | B24: G030 | C24: 6"-BFW-9202-BG4A-H25 (2/2) | D24: =LEFT(C24, FIND("""", C24)) -> 6" | E24: 300 | F24: GV1 | I24: 1
A25: 12 | B25: G031 | C25: 3"-BFW-9205-AG1 B-H25 | D25: =LEFT(C25, FIND("""", C25)) -> 3" | I25: 1
A26: 13 | B26: G032 | C26: 3"-BFW-9205-AG 1B-H25 | D26: =LEFT(C26, FIND("""", C26)) -> 3" | E26: 300 | F26: GV1 | I26: 1
A27: 14 | B27: G033 | C27: 3"-BFW-9205-AG 1B-H25 | D27: =LEFT(C27, FIND("""", C27)) -> 3" | E27: 300 | F27: GV1 | I27: 1
A28: 15 | B28: G051 | C28: 2"-CWR-9421 -AG 1A | D28: =LEFT(C28, FIND("""", C28)) -> 2" | I28: 1
A29: 16 | B29: G052 | C29: 2"-CWR-8000-AG1A | D29: =LEFT(C29, FIND("""", C29)) -> 2" | I29: 1
A30: 17 | B30: G061 | C30: 2"-CWR-9406-AG 1A | D30: =LEFT(C30, FIND("""", C30)) -> 2" | E30: 150 | F30: BV | I30: 1
A31: 18 | B31: G062 | C31: 20"-CWR-9451-AG1A | D31: =LEFT(C31, FIND("""", C31)) -> 20" | E31: 150 | F31: BV2 | I31: 1
A32: 19 | B32: G063 | C32: 4"-CWR-8501-AG1A | D32: =LEFT(C32, FIND("""", C32)) -> 4" | E32: 150 | F32: GLV | I32: 1
A33: 20 | B33: G064 | C33: 2"-CWR-8000-AG 1A | D33: =LEFT(C33, FIND("""", C33)) -> 2" | E33: 150 | F33: GV1 | I33: 1
A34: 21 | B34: G065 | C34: 8"-CWR-9401 -AG 1A | D34: =LEFT(C34, FIND("""", C34)) -> 8"
A35: 22 | B35: G067 | C35: 4"-CWR-9410-AG1A | D35: =LEFT(C35, FIND("""", C35)) -> 4" | E35: 150 | F35: BV1 | I35: 1
A36: 23 | B36: G068 | C36: 2"-WCR-9403-AG 1A | D36: =LEFT(C36, FIND("""", C36)) -> 2" | E36: 150 | F36: BV2 | I36: 1
A37: 24 | B37: G091 | C37: 28"-CWS-9400-AG 1A | D37: =LEFT(C37, FIND("""", C37)) -> 28" | E37: 150 | F37: BV1 | I37: 1
A38: 25 | B38: G092 | C38: 28"-CWS-9400-AG 1A | D38: =LEFT(C38, FIND("""", C38)) -> 28" | E38: 150 | F38: BV1 | I38: 1
A39: 26 | B39: G093 | C39: 2"-CWS-9406-AG 1A | D39: =LEFT(C39, FIND("""", C39)) -> 2" | I39: 1
A40: 27 | B40: G094 | C40: 6"-CWS-9407-AG 1A | D40: =LEFT(C40, FIND("""", C40)) -> 6" | I40: 1
A41: 28 | B41: G095 | C41: 20"-CWS-9451 -AG 1A (1/2) (2/2) | D41: =LEFT(C41, FIND("""", C41)) -> 20" | E41: 150 | F41: CV | I41: 1
D42: 20" | E42: 150 | F42: BV
...

Sheet 49
C1: EQUIPMENT LIST | G1: Document No. | J1: : MNTC-ME
G2: Revision | J2: : 0
G3: Date of issue | J3: : 2025
A4: PT. PETRO OXO NUSANTARA | G4: Page | J4: :
A5: PIPING LIST UTILITY & TANK YARD
A7: No | B7: Line No. | C7: Size | D7: Service | E7: Fluid | F7: Material | G7: Insulation | H7: Drawing | I7: PAGE NO. | J7: Pipe length ( mm )
A8: 1 | B8: 2"-BBD-9201 -AG 1B-H25 | C8: =LEFT(B8, FIND("""", B8)) -> 2" | D8: Boiler Blow Down | E8: Water | F8: CS | G8: Hot | H8: =HYPERLINK("\\CAD-PC\1Data\3.Documentation\Isometric DWG MHI\" & I8 & ".pdf", "Drawing") -> Drawing | I8: G011
A9: 2 | B9: 2"-BFW-8507-AG 1B-P | C9: =LEFT(B9, FIND("""", B9)) -> 2" | D9: Boiler Feed Water | E9: Water | F9: CS | H9: =HYPERLINK("\\CAD-PC\1Data\3.Documentation\Isometric DWG MHI\" & I9 & ".pdf", "Drawing") -> Drawing | I9: G021
A10: 3 | B10: 2"-BFW-8505-AG 1B-P (1/2) (2/2) | C10: =LEFT(B10, FIND("""", B10)) -> 2" | D10: Boiler Feed Water | E10: Water | F10: CS | H10: =HYPERLINK("\\CAD-PC\1Data\3.Documentation\Isometric DWG MHI\" & I10 & ".pdf", "Drawing") -> Drawing | I10: G022
A11: 4 | B11: 3"-BFW-8503-AG 1 B-P | C11: =LEFT(B11, FIND("""", B11)) -> 3" | D11: Boiler Feed Water | E11: Water | F11: CS | H11: =HYPERLINK("\\CAD-PC\1Data\3.Documentation\Isometric DWG MHI\" & I11 & ".pdf", "Drawing") -> Drawing | I11: G023
A12: 5 | B12: 2-1/2"-BFW-8508- AG1B-P | C12: =LEFT(B12, FIND("""", B12)) -> 2-1/2" | D12: Boiler Feed Water | E12: Water | F12: CS | H12: =HYPERLINK("\\CAD-PC\1Data\3.Documentation\Isometric DWG MHI\" & I12 & ".pdf", "Drawing") -> Drawing | I12: G024
A13: 6 | B13: 8"-BFW-9201 -AG 1B-H25 | C13: =LEFT(B13, FIND("""", B13)) -> 8" | D13: Boiler Feed Water | E13: Water | F13: CS | G13: Hot | H13: =HYPERLINK("\\CAD-PC\1Data\3.Documentation\Isometric DWG MHI\" & I13 & ".pdf", "Drawing") -> Drawing | I13: G025
A14: 7 | B14: 8"-BFW-9201-AG 1B-H25 | C14: =LEFT(B14, FIND("""", B14)) -> 8" | D14: Boiler Feed Water | E14: Water | F14: CS | G14: Hot | H14: =HYPERLINK("\\CAD-PC\1Data\3.Documentation\Isometric DWG MHI\" & I14 & ".pdf", "Drawing") -> Drawing | I14: G026
A15: 8 | B15: 8"-BFW-9201 -AG 1B-H25 | C15: =LEFT(B15, FIND("""", B15)) -> 8" | D15: Boiler Feed Water | E15: Water | F15: CS | G15: Hot | H15: =HYPERLINK("\\CAD-PC\1Data\3.Documentation\Isometric DWG MHI\" & I15 & ".pdf", "Drawing") -> Drawing | I15: G027
A16: 9 | B16: 4"-BFW-9202-BG4A- H25 | C16: =LEFT(B16, FIND("""", B16)) -> 4" | D16: Boiler Feed Water | E16: Water | F16: CS | G16: Hot | H16: =HYPERLINK("\\CAD-PC\1Data\3.Documentation\Isometric DWG MHI\" & I16 & ".pdf", "Drawing") -> Drawing | I16: G028
A17: 10 | B17: 6"-BFW-9202-BG4A-H25 (1/2) | C17: =LEFT(B17, FIND("""", B17)) -> 6" | D17: Boiler Feed Water | E17: Water | F17: CS | G17: Hot | H17: =HYPERLINK("\\CAD-PC\1Data\3.Documentation\Isometric DWG MHI\" & I17 & ".pdf", "Drawing") -> Drawing | I17: G029
A18: 11 | B18: 6"-BFW-9202-BG4A-H25 (2/2) | C18: =LEFT(B18, FIND("""", B18)) -> 6" | D18: Boiler Feed Water | E18: Water | F18: CS | G18: Hot | H18: =HYPERLINK("\\CAD-PC\1Data\3.Documentation\Isometric DWG MHI\" & I18 & ".pdf", "Drawing") -> Drawing | I18: G030
A19: 12 | B19: 3"-BFW-9205-AG1 B-H25 | C19: =LEFT(B19, FIND("""", B19)) -> 3" | D19: Boiler Feed Water | E19: Water | F19: CS | G19: Hot | H19: =HYPERLINK("\\CAD-PC\1Data\3.Documentation\Isometric DWG MHI\" & I19 & ".pdf", "Drawing") -> Drawing | I19: G031
A20: 13 | B20: 3"-BFW-9205-AG 1B-H25 | C20: =LEFT(B20, FIND("""", B20)) -> 3" | D20: Boiler Feed Water | E20: Water | F20: CS | G20: Hot | H20: =HYPERLINK("\\CAD-PC\1Data\3.Documentation\Isometric DWG MHI\" & I20 & ".pdf", "Drawing") -> Drawing | I20: G032
A21: 14 | B21: 3"-BFW-9205-AG 1B-H25 | C21: =LEFT(B21, FIND("""", B21)) -> 3" | D21: Boiler Feed Water | E21: Water | F21: CS | G21: Hot | H21: =HYPERLINK("\\CAD-PC\1Data\3.Documentation\Isometric DWG MHI\" & I21 & ".pdf", "Drawing") -> Drawing | I21: G033
A22: 15 | B22: 2"-CWR-9421 -AG 1A | C22: =LEFT(B22, FIND("""", B22)) -> 2" | D22: Cooling Water | E22: Water | F22: CS | H22: =HYPERLINK("\\CAD-PC\1Data\3.Documentation\Isometric DWG MHI\" & I22 & ".pdf", "Drawing") -> Drawing | I22: G051
A23: 16 | B23: 2"-CWR-8000-AG1A | C23: =LEFT(B23, FIND("""", B23)) -> 2" | D23: Cooling Water | E23: Water | F23: CS | H23: =HYPERLINK("\\CAD-PC\1Data\3.Documentation\Isometric DWG MHI\" & I23 & ".pdf", "Drawing") -> Drawing | I23: G052
A24: 17 | B24: 2"-CWR-9406-AG 1A | C24: =LEFT(B24, FIND("""", B24)) -> 2" | D24: Cooling Water | E24: Water | F24: CS | H24: =HYPERLINK("\\CAD-PC\1Data\3.Documentation\Isometric DWG MHI\" & I24 & ".pdf", "Drawing") -> Drawing | I24: G061
A25: 18 | B25: 20"-CWR-9451-AG1A | C25: =LEFT(B25, FIND("""", B25)) -> 20" | D25: Cooling Water | E25: Water | F25: CS | H25: =HYPERLINK("\\CAD-PC\1Data\3.Documentation\Isometric DWG MHI\" & I25 & ".pdf", "Drawing") -> Drawing | I25: G062
A26: 19 | B26: 4"-CWR-8501-AG1A | C26: =LEFT(B26, FIND("""", B26)) -> 4" | D26: Cooling Water | E26: Water | F26: CS | H26: =HYPERLINK("\\CAD-PC\1Data\3.Documentation\Isometric DWG MHI\" & I26 & ".pdf", "Drawing") -> Drawing | I26: G063
A27: 20 | B27: 2"-CWR-8000-AG 1A | C27: =LEFT(B27, FIND("""", B27)) -> 2" | D27: Cooling Water | E27: Water | F27: CS | H27: =HYPERLINK("\\CAD-PC\1Data\3.Documentation\Isometric DWG MHI\" & I27 & ".pdf", "Drawing") -> Drawing | I27: G064
A28: 21 | B28: 8"-CWR-9401 -AG 1A | C28: =LEFT(B28, FIND("""", B28)) -> 8" | D28: Cooling Water | E28: Water | F28: CS | H28: =HYPERLINK("\\CAD-PC\1Data\3.Documentation\Isometric DWG MHI\" & I28 & ".pdf", "Drawing") -> Drawing | I28: G065
A29: 22 | B29: 4"-CWR-9410-AG1A | C29: =LEFT(B29, FIND("""", B29)) -> 4" | D29: Cooling Water | E29: Water | F29: CS | H29: =HYPERLINK("\\CAD-PC\1Data\3.Documentation\Isometric DWG MHI\" & I29 & ".pdf", "Drawing") -> Drawing | I29: G067
A30: 23 | B30: 2"-WCR-9403-AG 1A | C30: =LEFT(B30, FIND("""", B30)) -> 2" | D30: Cooling Water | E30: Water | F30: CS | H30: =HYPERLINK("\\CAD-PC\1Data\3.Documentation\Isometric DWG MHI\" & I30 & ".pdf", "Drawing") -> Drawing | I30: G068
A31: 24 | B31: 28"-CWS-9400-AG 1A | C31: =LEFT(B31, FIND("""", B31)) -> 28" | D31: Cooling Water | E31: Water | F31: CS | H31: =HYPERLINK("\\CAD-PC\1Data\3.Documentation\Isometric DWG MHI\" & I31 & ".pdf", "Drawing") -> Drawing | I31: G091
A32: 25 | B32: 28"-CWS-9400-AG 1A | C32: =LEFT(B32, FIND("""", B32)) -> 28" | D32: Cooling Water | E32: Water | F32: CS | H32: =HYPERLINK("\\CAD-PC\1Data\3.Documentation\Isometric DWG MHI\" & I32 & ".pdf", "Drawing") -> Drawing | I32: G092
A33: 26 | B33: 2"-CWS-9406-AG 1A | C33: =LEFT(B33, FIND("""", B33)) -> 2" | D33: Cooling Water | E33: Water | F33: CS | H33: =HYPERLINK("\\CAD-PC\1Data\3.Documentation\Isometric DWG MHI\" & I33 & ".pdf", "Drawing") -> Drawing | I33: G093
... A82: 75 | B82: 3"-G PI -9901 -AG 1A | C82: =LEFT(B82, FIND("""", B82)) -> 3" | D82: Instrument Air | E82: Air | F82: CS | H82: =HYPERLINK("\\CAD-PC\1Data\3.Documentation\Isometric DWG MHI\" & I82 & ".pdf", "Drawing") -> Drawing | I82: G245
A83: 76 | B83: 6"-LPC-9202-AS 1A-H30 | C83: =LEFT(B83, FIND("""", B83)) -> 6" | D83: Condensate | E83: Water | F83: SS304 | G83: Hot | H83: =HYPERLINK("\\CAD-PC\1Data\3.Documentation\Isometric DWG MHI\" & I83 & ".pdf", "Drawing") -> Drawing | I83: G271
A84: 77 | B84: 6"-LPC-9202-AG 1B-H30 | C84: =LEFT(B84, FIND("""", B84)) -> 6" | D84: Condensate | E84: Water | F84: CS | G84: Hot | H84: =HYPERLINK("\\CAD-PC\1Data\3.Documentation\Isometric DWG MHI\" & I84 & ".pdf", "Drawing") -> Drawing | I84: G272
A85: 78 | B85: 2"-LPS-8504-AG 1A | C85: =LEFT(B85, FIND("""", B85)) -> 2" | D85: Low Pressure Steam | E85: Steam | F85: CS | H85: =HYPERLINK("\\CAD-PC\1Data\3.Documentation\Isometric DWG MHI\" & I85 & ".pdf", "Drawing") -> Drawing | I85: G281
A86: 79 | B86: 6"-LPS-9201 -AG1B-H30 (1/2) (2/2) | C86: =LEFT(B86, FIND("""", B86)) -> 6" | D86: Low Pressure Steam | E86: Steam | F86: CS | G86: Hot | H86: =HYPERLINK("\\CAD-PC\1Data\3.Documentation\Isometric DWG MHI\" & I86 & ".pdf", "Drawing") -> Drawing | I86: G282
A87: 80 | B87: 10"-MPS-9210-BG4A-H40 | C87: =LEFT(B87, FIND("""", B87)) -> 10" | D87: Medium Pressure Steam | E87: Steam | F87: CS | G87: Hot | H87: =HYPERLINK("\\CAD-PC\1Data\3.Documentation\Isometric DWG MHI\" & I87 & ".pdf", "Drawing") -> Drawing | I87: G311
A88: 81 | B88: 8"-M PS-9210-BG4A-H40 | C88: =LEFT(B88, FIND("""", B88)) -> 8" | D88: Medium Pressure Steam | E88: Steam | F88: CS | G88: Hot | H88: =HYPERLINK("\\CAD-PC\1Data\3.Documentation\Isometric DWG MHI\" & I88 & ".pdf", "Drawing") -> Drawing | I88: G312
A89: 82 | B89: 3"-NGS-9902-AG 1A | C89: =LEFT(B89, FIND("""", B89)) -> 3" | D89: Nitrogen Gas | E89: Gas | F89: CS | H89: =HYPERLINK("\\CAD-PC\1Data\3.Documentation\Isometric DWG MHI\" & I89 & ".pdf", "Drawing") -> Drawing | I89: G331
...

Sheet 48-1
C1: EQUIPMENT LIST | F1: Document No. | G1: : MNTC-ME
F2: Revision | G2: : 0
F3: Date of issue | G3: : 2025
A4: PT. PETRO OXO NUSANTARA | F4: Page | G4: :
A5: VALVE LIST OCTANOL
A7: No | B7: Line No. | C7: PAGE NO. | D7: Dia. | E7: Valve ID | F7: Material | G7: Remark
A8: 1 | B8: 3/4" - DMW-HS124 - AS1A | C8: E065 | D8: 3/4" | F8: A312-TP304 | H8: 1
A9: 2 | B9: 3/4" - DMW-HS142 - AS1A | C9: E066 | D9: 3/4" | E9: GV 1 | F9: A312-TP304 | H9: 1
A10: 3 | B10: 3/4" - DMW-HS152 - AS1A | C10: E067 | D10: 3/4" | F10: A312-TP304
A11: 4 | B11: 3/4" - DMW-HS162 - AS1A | C11: E068 | D11: 3/4" | E11: GV 1 | F11: A312-TP304 | H11: 1
A12: 5 | B12: 1 1/2" - FGS-6105-1 - AG1C | C12: E089 | D12: 1 1/2" | F12: CS
A13: 6 | B13: 3/4" - FGS-9621 - AG1C | C13: E090 | D13: 3/4" | F13: CS
A14: 7 | B14: 1 1/2" - FGS-5105 - AG1C | C14: E091 | D14: 1 1/2" | F14: CS
A15: 8 | B15: 1 1/2" - FGS-5105-2 - AG1A | C15: E092 | D15: 1 1/2" | F15: CS
A16: 9 | B16: 1 1/2" - FGS-6105-2 - AG1C | C16: E093 | D16: 1 1/2" | F16: CS
A17: 10 | B17: 1 1/2" - FWS-9383 - AG1A | C17: E104 | D17: 1 1/2" | E17: GV 2 | F17: CS | H17: 1
A18: 11 | B18: 1" - FWS-9384 - AG1A | C18: E106 | D18: 1" | F18: CS
A19: 12 | B19: 1" - FWS-HS144-1 - AG1A | C19: E109 | D19: 1" | F19: CS
A20: 13 | B20: 1" - FWS-HS155-1 - AG1A | C20: E110 | D20: 1" | F20: CS
A21: 14 | B21: 3/4" - FWS-HS101 - AG1A | C21: E127 | D21: 3/4" | E21: GV 1 | F21: CS | H21: 1
A22: 15 | B22: 3/4" - FWS-HS102 - AG1A | C22: E128 | D22: 3/4" | E22: GV 1 | F22: CS | H22: 1
A23: 16 | B23: 3/4" - FWS-HS103 - AG1A | C23: E129 | D23: 3/4" | E23: GV 1 | F23: CS | H23: 1
A24: 17 | B24: 3/4" - FWS-HS104 - AG1A | C24: E130 | D24: 3/4" | F24: CS
A25: 18 | B25: 3/4" - FWS-HS105 - AG1A | C25: E131 | D25: 3/4" | E25: GV 1 | F25: CS | H25: 1
A26: 19 | B26: 3/4" - FWS-HS106 - AG1A | C26: E132 | D26: 3/4" | F26: CS
A27: 20 | B27: 3/4" - FWS-HS107 - AG1A | C27: E133 | D27: 3/4" | F27: CS
A28: 21 | B28: 3/4" - FWS-HS108 - AG1A | C28: E134 | D28: 3/4" | F28: CS
A29: 22 | B29: 3/4" - FWS-HS109 - AG1A | C29: E135 | D29: 3/4" | F29: CS
A30: 23 | B30: 3/4" - FWS-HS110 - AG1A | C30: E136 | D30: 3/4" | E30: GV 1 | F30: CS | H30: 1
A31: 24 | B31: 3/4" - FWS-HS111 - AG1A | C31: E137 | D31: 3/4" | F31: CS
A32: 25 | B32: 3/4" - FWS-HS121 - AG1A | C32: E138 | D32: 3/4" | E32: GV 1 | F32: CS | H32: 1
A33: 26 | B33: 3/4" - FWS-HS122 - AG1A | C33: E139 | D33: 3/4" | F33: CS
A34: 27 | B34: 3/4" - FWS-HS123 - AG1A | C34: E140 | D34: 3/4" | F34: CS
A35: 28 | B35: 3/4" - FWS-HS124 - AG1A | C35: E141 | D35: 3/4" | F35: CS
A36: 29 | B36: 3/4" - FWS-HS141 - AG1A | C36: E142 | D36: 3/4" | E36: GV 1 | F36: CS | H36: 1
A37: 30 | B37: 3/4" - FWS-HS142 - AG1A | C37: E143 | D37: 3/4" | E37: GV 1 | F37: CS | H37: 1
A38: 31 | B38: 3/4" - FWS-HS143 - AG1A | C38: E144 | D38: 3/4" | F38: CS
A39: 32 | B39: 3/4" - FWS-HS144-2 - AG1A | C39: E145 | D39: 3/4" | F39: CS
A40: 33 | B40: 3/4" - FWS-HS145 - AG1A | C40: E146 | D40: 3/4" | F40: CS
A41: 34 | B41: 3/4" - FWS-HS151 - AG1A | C41: E147 | D41: 3/4" | E41: GV 1 | F41: CS | H41: 1
...

Sheet 48
C1: EQUIPMENT LIST | G1: Document No. | J1: : MNTC-ME
G2: Revision | J2: : 0
G3: Date of issue | J3: : 2025
A4: PT. PETRO OXO NUSANTARA | G4: Page | J4: :
A5: PIPING LIST OCTANOL
A7: No | B7: Line No. | C7: Size | D7: Service | E7: Fluid | F7: Material | G7: Insulation | H7: Drawing | I7: PAGE NO. | J7: Pipe length ( mm )
A8: 1 | B8: 3/4" - DMW-HS124 - AS1A | C8: 3/4" | D8: DEMINERALIZED WATER | E8: WATER | F8: A312-TP304 | H8: =HYPERLINK("\\CAD-PC\1Data\3.Documentation\Isometric DWG MHI\" & I8 & ".pdf", "Drawing") -> Drawing | I8: E065
A9: 2 | B9: 3/4" - DMW-HS142 - AS1A | C9: 3/4" | D9: DEMINERALIZED WATER | E9: WATER | F9: A312-TP304 | H9: =HYPERLINK("\\CAD-PC\1Data\3.Documentation\Isometric DWG MHI\" & I9 & ".pdf", "Drawing") -> Drawing | I9: E066
A10: 3 | B10: 3/4" - DMW-HS152 - AS1A | C10: 3/4" | D10: DEMINERALIZED WATER | E10: WATER | F10: A312-TP304 | H10: =HYPERLINK("\\CAD-PC\1Data\3.Documentation\Isometric DWG MHI\" & I10 & ".pdf", "Drawing") -> Drawing | I10: E067
A11: 4 | B11: 3/4" - DMW-HS162 - AS1A | C11: 3/4" | D11: DEMINERALIZED WATER | E11: WATER | F11: A312-TP304 | H11: =HYPERLINK("\\CAD-PC\1Data\3.Documentation\Isometric DWG MHI\" & I11 & ".pdf", "Drawing") -> Drawing | I11: E068
A12: 5 | B12: 1 1/2" - FGS-6105-1 - AG1C | C12: 1 1/2" | D12: FUEL GAS | E12: GAS | F12: CS | H12: =HYPERLINK("\\CAD-PC\1Data\3.Documentation\Isometric DWG MHI\" & I12 & ".pdf", "Drawing") -> Drawing | I12: E089
A13: 6 | B13: 3/4" - FGS-9621 - AG1C | C13: 3/4" | D13: FUEL GAS | E13: GAS | F13: CS | H13: =HYPERLINK("\\CAD-PC\1Data\3.Documentation\Isometric DWG MHI\" & I13 & ".pdf", "Drawing") -> Drawing | I13: E090
A14: 7 | B14: 1 1/2" - FGS-5105 - AG1C | C14: 1 1/2" | D14: FUEL GAS | E14: GAS | F14: CS | H14: =HYPERLINK("\\CAD-PC\1Data\3.Documentation\Isometric DWG MHI\" & I14 & ".pdf", "Drawing") -> Drawing | I14: E091
A15: 8 | B15: 1 1/2" - FGS-5105-2 - AG1A | C15: 1 1/2" | D15: FUEL GAS | E15: GAS | F15: CS | H15: =HYPERLINK("\\CAD-PC\1Data\3.Documentation\Isometric DWG MHI\" & I15 & ".pdf", "Drawing") -> Drawing | I15: E092
A16: 9 | B16: 1 1/2" - FGS-6105-2 - AG1C | C16: 1 1/2" | D16: FUEL GAS | E16: GAS | F16: CS | H16: =HYPERLINK("\\CAD-PC\1Data\3.Documentation\Isometric DWG MHI\" & I16 & ".pdf", "Drawing") -> Drawing | I16: E093
A17: 10 | B17: 1 1/2" - FWS-9383 - AG1A | C17: 1 1/2" | D17: FILTERED WATER | E17: WATER | F17: CS | H17: =HYPERLINK("\\CAD-PC\1Data\3.Documentation\Isometric DWG MHI\" & I17 & ".pdf", "Drawing") -> Drawing | I17: E104
A18: 11 | B18: 1" - FWS-9384 - AG1A | C18: 1" | D18: FILTERED WATER | E18: WATER | F18: CS | H18: =HYPERLINK("\\CAD-PC\1Data\3.Documentation\Isometric DWG MHI\" & I18 & ".pdf", "Drawing") -> Drawing | I18: E106
A19: 12 | B19: 1" - FWS-HS144-1 - AG1A | C19: 1" | D19: FILTERED WATER | E19: WATER | F19: CS | H19: =HYPERLINK("\\CAD-PC\1Data\3.Documentation\Isometric DWG MHI\" & I19 & ".pdf", "Drawing") -> Drawing | I19: E109
... A102: 95 | B102: 3/4" - IPA-2303 - AS1A | C102: 3/4" | D102: ISO PROPANOL | E102: LIQUID | F102: A312-TP304 | H102: =HYPERLINK("\\CAD-PC\1Data\3.Documentation\Isometric DWG MHI\" & I102 & ".pdf", "Drawing") -> Drawing | I102: E276
A103: 96 | B103: 3/4" - LPC-3159 - AG1B | C103: 3/4" | D103: STEAM CONDENSATE | E103: WATER | F103: CS | G103: H25 | H103: =HYPERLINK("\\CAD-PC\1Data\3.Documentation\Isometric DWG MHI\" & I103 & ".pdf", "Drawing") -> Drawing | I103: E286
A104: 97 | B104: 1 1/2" - LPC-5552-1 - AG1B | C104: 1 1/2" | D104: STEAM CONDENSATE | E104: WATER | F104: CS | G104: H25 | H104: =HYPERLINK("\\CAD-PC\1Data\3.Documentation\Isometric DWG MHI\" & I104 & ".pdf", "Drawing") -> Drawing | I104: E287
A105: 98 | B105: 1 1/2" - LPC-9203 - AG1B | C105: 1 1/2" | D105: STEAM CONDENSATE | E105: WATER | F105: CS | G105: H25 | H105: =HYPERLINK("\\CAD-PC\1Data\3.Documentation\Isometric DWG MHI\" & I105 & ".pdf", "Drawing") -> Drawing | I105: E288
A106: 99 | B106: 3/4" - LPC-2556 - AG1B | C106: 3/4" | D106: STEAM CONDENSATE | E106: WATER | F106: CS | H106: =HYPERLINK("\\CAD-PC\1Data\3.Documentation\Isometric DWG MHI\" & I106 & ".pdf", "Drawing") -> Drawing | I106: E290
A107: 100 | B107: 1 1/2" - LPC-3159 - AG1B | C107: 1 1/2" | D107: STEAM CONDENSATE | E107: WATER | F107: CS | G107: H25 | H107: =HYPERLINK("\\CAD-PC\1Data\3.Documentation\Isometric DWG MHI\" & I107 & ".pdf", "Drawing") -> Drawing | I107: E291
A108: 101 | B108: 3/4" - LPC-HOLD - AG1B | C108: 3/4" | D108: STEAM CONDENSATE | E108: WATER | F108: CS | G108: H25 | H108: =HYPERLINK("\\CAD-PC\1Data\3.Documentation\Isometric DWG MHI\" & I108 & ".pdf", "Drawing") -> Drawing | I108: E292
A109: 102 | B109: 1" - LPS-9283 - AG1B | C109: 1" | D109: LOW PRESSURE STEAM | E109: STEAM | F109: CS | G109: H25 | H109: =HYPERLINK("\\CAD-PC\1Data\3.Documentation\Isometric DWG MHI\" & I109 & ".pdf", "Drawing") -> Drawing | I109: E312
A110: 103 | B110: 1" - LPS-HS144-1 - AG1B | C110: 1" | D110: LOW PRESSURE STEAM | E110: STEAM | F110: CS | G110: H25 | H110: =HYPERLINK("\\CAD-PC\1Data\3.Documentation\Isometric DWG MHI\" & I110 & ".pdf", "Drawing") -> Drawing | I110: E315
A111: 104 | B111: 1" - LPS-HS155-1 - AG1B | C111: 1" | D111: LOW PRESSURE STEAM | E111: STEAM | F111: CS | G111: H25 | H111: =HYPERLINK("\\CAD-PC\1Data\3.Documentation\Isometric DWG MHI\" & I111 & ".pdf", "Drawing") -> Drawing | I111: E316
A112: 105 | B112: 3/4" - LPS-HS101 - AG1B | C112: 3/4" | D112: LOW PRESSURE STEAM | E112: STEAM | F112: CS | G112: H25 | H112: =HYPERLINK("\\CAD-PC\1Data\3.Documentation\Isometric DWG MHI\" & I112 & ".pdf", "Drawing") -> Drawing | I112: E346
A113: 106 | B113: 3/4" - LPS-HS102 - AG1B | C113: 3/4" | D113: LOW PRESSURE STEAM | E113: STEAM | F113: CS | G113: H25 | H113: =HYPERLINK("\\CAD-PC\1Data\3.Documentation\Isometric DWG MHI\" & I113 & ".pdf", "Drawing") -> Drawing | I113: E347
A114: 107 | B114: 3/4" - LPS-HS103 - AG1A | C114: 3/4" | D114: LOW PRESSURE STEAM | E114: STEAM | F114: CS | G114: H25 | H114: =HYPERLINK("\\CAD-PC\1Data\3.Documentation\Isometric DWG MHI\" & I114 & ".pdf", "Drawing") -> Drawing | I114: E348
A115: 108 | B115: 3/4" - LPS-HS104 - AG1B | C115: 3/4" | D115: LOW PRESSURE STEAM | E115: STEAM | F115: CS | G115: H25 | H115: =HYPERLINK("\\CAD-PC\1Data\3.Documentation\Isometric DWG MHI\" & I115 & ".pdf", "Drawing") -> Drawing | I115: E349
A116: 109 | B116: 3/4" - LPS-HS105 - AG1B | C116: 3/4" | D116: LOW PRESSURE STEAM | E116: STEAM | F116: CS | G116: H25 | H116: =HYPERLINK("\\CAD-PC\1Data\3.Documentation\Isometric DWG MHI\" & I116 & ".pdf", "Drawing") -> Drawing | I116: E350
A117: 110 | B117: 3/4" - LPS-HS106 - AG1B | C117: 3/4" | D117: LOW PRESSURE STEAM | E117: STEAM | F117: CS | G117: H25 | H117: =HYPERLINK("\\CAD-PC\1Data\3.Documentation\Isometric DWG MHI\" & I117 & ".pdf", "Drawing") -> Drawing | I117: E351
A118: 111 | B118: 3/4" - LPS-HS107 - AG1B | C118: 3/4" | D118: LOW PRESSURE STEAM | E118: STEAM | F118: CS | G118: H25 | H118: =HYPERLINK("\\CAD-PC\1Data\3.Documentation\Isometric DWG MHI\" & I118 & ".pdf", "Drawing") -> Drawing | I118: E352
... A156: 149 | B156: 1 1/2" - MPS-2254 - AG4A | C156: 1 1/2" | D156: MEDIUM PRESSURE STEAM | E156: STEAM | F156: CS | G156: H25 | H156: =HYPERLINK("\\CAD-PC\1Data\3.Documentation\Isometric DWG MHI\" & I156 & ".pdf", "Drawing") -> Drawing | I156: E417
A157: 150 | B157: 3/4" - P-4555 - BG4A | C157: 3/4" | D157: PROCESS | F157: CS | G157: H25 | H157: =HYPERLINK("\\CAD-PC\1Data\3.Documentation\Isometric DWG MHI\" & I157 & ".pdf", "Drawing") -> Drawing | I157: E418
A158: 151 | B158: 1" - MPS-4556 - BG4A | C158: 1" | D158: MEDIUM PRESSURE STEAM | E158: STEAM | F158: CS | G158: H25 | H158: =HYPERLINK("\\CAD-PC\1Data\3.Documentation\Isometric DWG MHI\" & I158 & ".pdf", "Drawing") -> Drawing | I158: E419
A159: 152 | B159: 1 1/2" - MPS-5451 - BG4A | C159: 1 1/2" | D159: MEDIUM PRESSURE STEAM | E159: STEAM | F159: CS | G159: H25 | H159: =HYPERLINK("\\CAD-PC\1Data\3.Documentation\Isometric DWG MHI\" & I159 & ".pdf", "Drawing") -> Drawing | I159: E421
A160: 153 | B160: 1 1/2" - MPS-6451-1 - BG4A | C160: 1 1/2" | D160: MEDIUM PRESSURE STEAM | E160: STEAM | F160: CS | G160: H25 | H160: =HYPERLINK("\\CAD-PC\1Data\3.Documentation\Isometric DWG MHI\" & I160 & ".pdf", "Drawing") -> Drawing | I160: E422
...

Sheet 47-1
C1: EQUIPMENT LIST | G1: Document No. | H1: : MNTC-ME
G2: Revision | H2: : 0
G3: Date of issue | H3: : 2025
A4: PT. PETRO OXO NUSANTARA | G4: Page | H4: :
A5: VALVE LIST SYN GAS
A7: NO | B7: Code | C7: Line Number piping + accecories | D7: Diameter | E7: SCH | F7: Valve | G7: Material | H7: Remark
A9: Syngas
A10: 1 | B10: A001 | C10: 2"-BBD-0155-BG4A-H25 | D10: =LEFT(C10, FIND("""", C10)) -> 2" | E10: 40 | F10: GV 1,2,3,4 | G10: Carbon steel | I10: 1
A11: 2 | B11: A002 | C11: 2"-BBD-0156-BG4A-H25 | D11: =LEFT(C11, FIND("""", C11)) -> 2" | E11: 40 | F11: GV1 | I11: 1
D12: 1/2" | F12: GV1 | I12: 1
D13: 1 1/2" | F13: GV1 | I13: 1
A14: 3 | B14: A003 | C14: 2"-BBD-0156-AG1B-H25 | D14: =LEFT(C14, FIND("""", C14)) -> 2" | E14: 40 | F14: GV1,2 | I14: 1
D15: 1 1/2" | F15: GV1,2 | I15: 1
A16: 4 | B16: A004 | C16: 2"-BBD-0157-BG4A-H25 | D16: =LEFT(C16, FIND("""", C16)) -> 2" | E16: 40 | F16: GV1,2,3,4 | I16: 1
A17: 5 | B17: A005 | C17: 2"-BBD-0157-BG4A | D17: =LEFT(C17, FIND("""", C17)) -> 2" | E17: 40 | F17: GV1 | I17: 1
A18: 6 | B18: A006 | C18: 10"-BBD-0157-BG4A | D18: =LEFT(C18, FIND("""", C18)) -> 10" | E18: 20 | I18: 1
A19: 7 | B19: A007 | C19: 2"-BBD-0156-AG1B-H25 | D19: =LEFT(C19, FIND("""", C19)) -> 2" | E19: 40
A20: 8 | B20: A008 | C20: 2"-BBD-0156-AG1B-H25 | D20: =LEFT(C20, FIND("""", C20)) -> 2" | E20: 40
A21: 9 | B21: A011 | C21: 4"-BFW-0173-BG4A-H25 | D21: =LEFT(C21, FIND("""", C21)) -> 4" | E21: 40 | F21: GV1 | I21: 1
D22: 3/4" | E22: 80 | F22: GV1 | I22: 1
D23: 1/2" | E23: 80 | F23: GV1,2 | I23: 1
A24: 10 | B24: A012 | C24: 4"-BFW-0182-BG4A-H30 | D24: =LEFT(C24, FIND("""", C24)) -> 4" | E24: 40 | F24: GV1,2 | I24: 1
A25: 11 | B25: A013 | C25: 4"-BFW-0182-BG4A-H30 | D25: =LEFT(C25, FIND("""", C25)) -> 4" | E25: 40 | F25: GV1 | I25: 1
D26: 4" | F26: CV1 | I26: 1
D27: 3/4" | F27: GV1 | I27: 1
A28: 12 | B28: A014 | C28: 4"-BFW-0182-BG4A-H30 | D28: =LEFT(C28, FIND("""", C28)) -> 4" | E28: 40 | I28: 1
A29: 13 | B29: A015 | C29: 4"-BFW-0173-BG4A-H25 | D29: =LEFT(C29, FIND("""", C29)) -> 4" | E29: 40 | I29: 1
A30: 14 | B30: A016 | C30: 4"-BFW-0173-BG4A-H25 | D30: =LEFT(C30, FIND("""", C30)) -> 4" | E30: 40 | I30: 1
A31: 15 | B31: A021 | C31: 6"-CWR-0274-AG1A | D31: =LEFT(C31, FIND("""", C31)) -> 6" | E31: 40 | I31: 1
A32: 16 | B32: A022 | C32: 6"-CWR-0175-AG1A | D32: =LEFT(C32, FIND("""", C32)) -> 6" | E32: 40 | F32: - | I32: 1
C33: Check valve | D33: 6" | F33: CV 1 | I33: 1
D34: 3/4" | F34: GV1 | I34: 1
A35: 17 | B35: A023 | C35: 6"-CWR-0276-AG1A | D35: =LEFT(C35, FIND("""", C35)) -> 6" | E35: 40 | F35: BV1 | I35: 1
A36: 18 | B36: A024 | C36: 2"-CWR-0278-AG1A | D36: =LEFT(C36, FIND("""", C36)) -> 2" | E36: 40 | I36: 1
A37: 19 | B37: A025 | C37: 3"-CWR-0372-AG1A | D37: =LEFT(C37, FIND("""", C37)) -> 3" | E37: 40 | I37: 1
A38: 20 | B38: A026 | C38: 14"-CWR-9465-AG1A | D38: =LEFT(C38, FIND("""", C38)) -> 14" | E38: 20 | I38: 1
D39: 2" | F39: GV1 | I39: 1
A40: 21 | B40: A027 | C40: 2"-CWR-0072-AG1A | D40: =LEFT(C40, FIND("""", C40)) -> 2" | I40: 1
A41: 22 | B41: A028 | C41: 2"-CWR-0072-AG1A | D41: =LEFT(C41, FIND("""", C41)) -> 2" | I41: 1
A42: 23 | B42: A029 | C42: 14"-CWR-9465-AG1A | D42: =LEFT(C42, FIND("""", C42)) -> 14" | E42: 20 | I42: 1
...

Sheet 47
D1: EQUIPMENT LIST | I1: Document No. | J1: : MNTC-ME
I2: Revision | J2: : 0
I3: Date of issue | J3: : 2025
A4: PT. PETRO OXO NUSANTARA | I4: Page | J4: :
A5: PIPING LIST SYN GAS
B7: No | C7: Line No. | D7: Size | E7: Service | F7: Fluid | G7: Material | H7: Insulation | I7: ISO Drawing | J7: PAGE NO. | K7: Pipe length ( mm )
B8: 1 | C8: 2"-BBD-0155-BG4A-H25 | D8: =LEFT(C8, FIND("""", C8)) -> 2" | E8: Boiler Blow Down | F8: Water & Steam | G8: CS | H8: H25 | I8: =HYPERLINK("\\CAD-PC\1Data\3.Documentation\Isometric DWG MHI\" & J8 & ".pdf", C8) -> 2"-BBD-0155-BG4A-H25 | J8: A001
B9: 2 | C9: 2"-BBD-0156-BG4A-H25 | D9: =LEFT(C9, FIND("""", C9)) -> 2" | E9: Boiler Blow Down | F9: Water & Steam | G9: CS | H9: H25 | I9: =HYPERLINK("\\CAD-PC\1Data\3.Documentation\Isometric DWG MHI\" & J9 & ".pdf", C9) -> 2"-BBD-0156-BG4A-H25 | J9: A002
B10: 3 | C10: 2"-BBD-0156-AG1B-H25 | D10: =LEFT(C10, FIND("""", C10)) -> 2" | E10: Boiler Blow Down | F10: Water & Steam | G10: CS | H10: H25 | I10: =HYPERLINK("\\CAD-PC\1Data\3.Documentation\Isometric DWG MHI\" & J10 & ".pdf", C10) -> 2"-BBD-0156-AG1B-H25 | J10: A003
B11: 4 | C11: 2"-BBD-0157-BG4A-H25 | D11: =LEFT(C11, FIND("""", C11)) -> 2" | E11: Boiler Blow Down | F11: Water & Steam | G11: CS | H11: H25 | I11: =HYPERLINK("\\CAD-PC\1Data\3.Documentation\Isometric DWG MHI\" & J11 & ".pdf", C11) -> 2"-BBD-0157-BG4A-H25 | J11: A004
B12: 5 | C12: 2"-BBD-0157-BG4A | D12: =LEFT(C12, FIND("""", C12)) -> 2" | E12: Boiler Blow Down | F12: Water & Steam | G12: CS | I12: =HYPERLINK("\\CAD-PC\1Data\3.Documentation\Isometric DWG MHI\" & J12 & ".pdf", C12) -> 2"-BBD-0157-BG4A | J12: A005
B13: 6 | C13: 10"-BBD-0157-BG4A | D13: =LEFT(C13, FIND("""", C13)) -> 10" | E13: Boiler Blow Down | F13: Water & Steam | G13: CS | I13: =HYPERLINK("\\CAD-PC\1Data\3.Documentation\Isometric DWG MHI\" & J13 & ".pdf", C13) -> 10"-BBD-0157-BG4A | J13: A006
B14: 7 | C14: 2"-BBD-0156-AG1B-H25 | D14: =LEFT(C14, FIND("""", C14)) -> 2" | E14: Boiler Blow Down | F14: Water & Steam | G14: CS | H14: H25 | I14: =HYPERLINK("\\CAD-PC\1Data\3.Documentation\Isometric DWG MHI\" & J14 & ".pdf", C14) -> 2"-BBD-0156-AG1B-H25 | J14: A007 | K14: 44545
